[2025-09-04 03:37:46,457] INFO django.utils.autoreload: Watching for file changes with StatReloader
[2025-09-04 03:37:50,438] INFO django.utils.autoreload: C:\Users\Coded\PRO-DEV\alx-backend-security\alx_backend_security\settings.py changed, reloading.
[2025-09-04 03:37:51,325] INFO django.utils.autoreload: Watching for file changes with StatReloader
[2025-09-04 03:37:56,403] INFO django.utils.autoreload: C:\Users\Coded\PRO-DEV\alx-backend-security\alx_backend_security\settings.py changed, reloading.
[2025-09-04 03:37:57,473] INFO django.utils.autoreload: Watching for file changes with StatReloader
[2025-09-04 03:37:59,601] INFO django.utils.autoreload: C:\Users\Coded\PRO-DEV\alx-backend-security\alx_backend_security\settings.py changed, reloading.
[2025-09-04 03:38:00,500] INFO django.utils.autoreload: Watching for file changes with StatReloader
[2025-09-04 03:38:02,504] INFO django.utils.autoreload: C:\Users\Coded\PRO-DEV\alx-backend-security\alx_backend_security\settings.py changed, reloading.
[2025-09-04 03:38:03,523] INFO django.utils.autoreload: Watching for file changes with StatReloader
[2025-09-04 03:38:25,995] INFO django.utils.autoreload: C:\Users\Coded\PRO-DEV\alx-backend-security\alx_backend_security\settings.py changed, reloading.
[2025-09-04 03:38:26,970] INFO django.utils.autoreload: Watching for file changes with StatReloader
[2025-09-04 03:38:44,505] INFO django.utils.autoreload: C:\Users\Coded\PRO-DEV\alx-backend-security\alx_backend_security\settings.py changed, reloading.
[2025-09-04 03:40:26,376] INFO django.utils.autoreload: Watching for file changes with StatReloader
[2025-09-04 03:51:05,353] ERROR django.request: Internal Server Error: /login/
Traceback (most recent call last):
  File "C:\dev\coded\Lib\site-packages\django_redis\cache.py", line 29, in _decorator
    return method(self, *args, **kwargs)
           ^^^^^^^^^^^^^^^^^^^^^^^^^^^^^
  File "C:\dev\coded\Lib\site-packages\django_redis\cache.py", line 99, in _get
    return self.client.get(key, default=default, version=version, client=client)
           ^^^^^^^^^^^^^^^^^^^^^^^^^^^^^^^^^^^^^^^^^^^^^^^^^^^^^^^^^^^^^^^^^^^^^
  File "C:\dev\coded\Lib\site-packages\django_redis\client\default.py", line 300, in get
    raise ConnectionInterrupted(connection=client) from e
django_redis.exceptions.ConnectionInterrupted: Redis ConnectionError: Error while reading from 127.0.0.1:6379 : (10054, 'An existing connection was forcibly closed by the remote host', None, 10054, None)

During handling of the above exception, another exception occurred:

Traceback (most recent call last):
  File "C:\dev\coded\Lib\site-packages\django\core\handlers\exception.py", line 55, in inner
    response = get_response(request)
               ^^^^^^^^^^^^^^^^^^^^^
  File "C:\Users\Coded\PRO-DEV\alx-backend-security\ip_tracking\middleware.py", line 42, in __call__
    ip_data = cache.get(cache_key)
              ^^^^^^^^^^^^^^^^^^^^
  File "C:\dev\coded\Lib\site-packages\django_redis\cache.py", line 92, in get
    value = self._get(key, default, version, client)
            ^^^^^^^^^^^^^^^^^^^^^^^^^^^^^^^^^^^^^^^^
  File "C:\dev\coded\Lib\site-packages\django_redis\cache.py", line 36, in _decorator
    raise e.__cause__  # noqa: B904
    ^^^^^^^^^^^^^^^^^
  File "C:\dev\coded\Lib\site-packages\django_redis\client\default.py", line 298, in get
    value = client.get(key)
            ^^^^^^^^^^^^^^^
  File "C:\dev\coded\Lib\site-packages\redis\commands\core.py", line 1829, in get
    return self.execute_command("GET", name, keys=[name])
           ^^^^^^^^^^^^^^^^^^^^^^^^^^^^^^^^^^^^^^^^^^^^^^
  File "C:\dev\coded\Lib\site-packages\redis\client.py", line 621, in execute_command
    return self._execute_command(*args, **options)
           ^^^^^^^^^^^^^^^^^^^^^^^^^^^^^^^^^^^^^^^
  File "C:\dev\coded\Lib\site-packages\redis\client.py", line 627, in _execute_command
    conn = self.connection or pool.get_connection()
                              ^^^^^^^^^^^^^^^^^^^^^
  File "C:\dev\coded\Lib\site-packages\redis\utils.py", line 195, in wrapper
    return func(*args, **kwargs)
           ^^^^^^^^^^^^^^^^^^^^^
  File "C:\dev\coded\Lib\site-packages\redis\connection.py", line 1533, in get_connection
    connection.connect()
  File "C:\dev\coded\Lib\site-packages\redis\connection.py", line 380, in connect
    self.connect_check_health(check_health=True)
  File "C:\dev\coded\Lib\site-packages\redis\connection.py", line 403, in connect_check_health
    self.on_connect_check_health(check_health=check_health)
  File "C:\dev\coded\Lib\site-packages\redis\connection.py", line 523, in on_connect_check_health
    self.read_response()
  File "C:\dev\coded\Lib\site-packages\redis\connection.py", line 658, in read_response
    raise ConnectionError(f"Error while reading from {host_error} : {e.args}")
redis.exceptions.ConnectionError: Error while reading from 127.0.0.1:6379 : (10054, 'An existing connection was forcibly closed by the remote host', None, 10054, None)
[2025-09-04 03:51:05,354] ERROR django.request: Internal Server Error: /login
Traceback (most recent call last):
  File "C:\dev\coded\Lib\site-packages\django_redis\cache.py", line 29, in _decorator
    return method(self, *args, **kwargs)
           ^^^^^^^^^^^^^^^^^^^^^^^^^^^^^
  File "C:\dev\coded\Lib\site-packages\django_redis\cache.py", line 99, in _get
    return self.client.get(key, default=default, version=version, client=client)
           ^^^^^^^^^^^^^^^^^^^^^^^^^^^^^^^^^^^^^^^^^^^^^^^^^^^^^^^^^^^^^^^^^^^^^
  File "C:\dev\coded\Lib\site-packages\django_redis\client\default.py", line 300, in get
    raise ConnectionInterrupted(connection=client) from e
django_redis.exceptions.ConnectionInterrupted: Redis ConnectionError: Error while reading from 127.0.0.1:6379 : (10054, 'An existing connection was forcibly closed by the remote host', None, 10054, None)

During handling of the above exception, another exception occurred:

Traceback (most recent call last):
  File "C:\dev\coded\Lib\site-packages\django\core\handlers\exception.py", line 55, in inner
    response = get_response(request)
               ^^^^^^^^^^^^^^^^^^^^^
  File "C:\Users\Coded\PRO-DEV\alx-backend-security\ip_tracking\middleware.py", line 42, in __call__
    ip_data = cache.get(cache_key)
              ^^^^^^^^^^^^^^^^^^^^
  File "C:\dev\coded\Lib\site-packages\django_redis\cache.py", line 92, in get
    value = self._get(key, default, version, client)
            ^^^^^^^^^^^^^^^^^^^^^^^^^^^^^^^^^^^^^^^^
  File "C:\dev\coded\Lib\site-packages\django_redis\cache.py", line 36, in _decorator
    raise e.__cause__  # noqa: B904
    ^^^^^^^^^^^^^^^^^
  File "C:\dev\coded\Lib\site-packages\django_redis\client\default.py", line 298, in get
    value = client.get(key)
            ^^^^^^^^^^^^^^^
  File "C:\dev\coded\Lib\site-packages\redis\commands\core.py", line 1829, in get
    return self.execute_command("GET", name, keys=[name])
           ^^^^^^^^^^^^^^^^^^^^^^^^^^^^^^^^^^^^^^^^^^^^^^
  File "C:\dev\coded\Lib\site-packages\redis\client.py", line 621, in execute_command
    return self._execute_command(*args, **options)
           ^^^^^^^^^^^^^^^^^^^^^^^^^^^^^^^^^^^^^^^
  File "C:\dev\coded\Lib\site-packages\redis\client.py", line 627, in _execute_command
    conn = self.connection or pool.get_connection()
                              ^^^^^^^^^^^^^^^^^^^^^
  File "C:\dev\coded\Lib\site-packages\redis\utils.py", line 195, in wrapper
    return func(*args, **kwargs)
           ^^^^^^^^^^^^^^^^^^^^^
  File "C:\dev\coded\Lib\site-packages\redis\connection.py", line 1533, in get_connection
    connection.connect()
  File "C:\dev\coded\Lib\site-packages\redis\connection.py", line 380, in connect
    self.connect_check_health(check_health=True)
  File "C:\dev\coded\Lib\site-packages\redis\connection.py", line 403, in connect_check_health
    self.on_connect_check_health(check_health=check_health)
  File "C:\dev\coded\Lib\site-packages\redis\connection.py", line 523, in on_connect_check_health
    self.read_response()
  File "C:\dev\coded\Lib\site-packages\redis\connection.py", line 658, in read_response
    raise ConnectionError(f"Error while reading from {host_error} : {e.args}")
redis.exceptions.ConnectionError: Error while reading from 127.0.0.1:6379 : (10054, 'An existing connection was forcibly closed by the remote host', None, 10054, None)
[2025-09-04 03:51:05,354] ERROR django.request: Internal Server Error: /login/
Traceback (most recent call last):
  File "C:\dev\coded\Lib\site-packages\django_redis\cache.py", line 29, in _decorator
    return method(self, *args, **kwargs)
           ^^^^^^^^^^^^^^^^^^^^^^^^^^^^^
  File "C:\dev\coded\Lib\site-packages\django_redis\cache.py", line 99, in _get
    return self.client.get(key, default=default, version=version, client=client)
           ^^^^^^^^^^^^^^^^^^^^^^^^^^^^^^^^^^^^^^^^^^^^^^^^^^^^^^^^^^^^^^^^^^^^^
  File "C:\dev\coded\Lib\site-packages\django_redis\client\default.py", line 300, in get
    raise ConnectionInterrupted(connection=client) from e
django_redis.exceptions.ConnectionInterrupted: Redis ConnectionError: Error while reading from 127.0.0.1:6379 : (10054, 'An existing connection was forcibly closed by the remote host', None, 10054, None)

During handling of the above exception, another exception occurred:

Traceback (most recent call last):
  File "C:\dev\coded\Lib\site-packages\django\core\handlers\exception.py", line 55, in inner
    response = get_response(request)
               ^^^^^^^^^^^^^^^^^^^^^
  File "C:\Users\Coded\PRO-DEV\alx-backend-security\ip_tracking\middleware.py", line 42, in __call__
    ip_data = cache.get(cache_key)
              ^^^^^^^^^^^^^^^^^^^^
  File "C:\dev\coded\Lib\site-packages\django_redis\cache.py", line 92, in get
    value = self._get(key, default, version, client)
            ^^^^^^^^^^^^^^^^^^^^^^^^^^^^^^^^^^^^^^^^
  File "C:\dev\coded\Lib\site-packages\django_redis\cache.py", line 36, in _decorator
    raise e.__cause__  # noqa: B904
    ^^^^^^^^^^^^^^^^^
  File "C:\dev\coded\Lib\site-packages\django_redis\client\default.py", line 298, in get
    value = client.get(key)
            ^^^^^^^^^^^^^^^
  File "C:\dev\coded\Lib\site-packages\redis\commands\core.py", line 1829, in get
    return self.execute_command("GET", name, keys=[name])
           ^^^^^^^^^^^^^^^^^^^^^^^^^^^^^^^^^^^^^^^^^^^^^^
  File "C:\dev\coded\Lib\site-packages\redis\client.py", line 621, in execute_command
    return self._execute_command(*args, **options)
           ^^^^^^^^^^^^^^^^^^^^^^^^^^^^^^^^^^^^^^^
  File "C:\dev\coded\Lib\site-packages\redis\client.py", line 627, in _execute_command
    conn = self.connection or pool.get_connection()
                              ^^^^^^^^^^^^^^^^^^^^^
  File "C:\dev\coded\Lib\site-packages\redis\utils.py", line 195, in wrapper
    return func(*args, **kwargs)
           ^^^^^^^^^^^^^^^^^^^^^
  File "C:\dev\coded\Lib\site-packages\redis\connection.py", line 1533, in get_connection
    connection.connect()
  File "C:\dev\coded\Lib\site-packages\redis\connection.py", line 380, in connect
    self.connect_check_health(check_health=True)
  File "C:\dev\coded\Lib\site-packages\redis\connection.py", line 403, in connect_check_health
    self.on_connect_check_health(check_health=check_health)
  File "C:\dev\coded\Lib\site-packages\redis\connection.py", line 523, in on_connect_check_health
    self.read_response()
  File "C:\dev\coded\Lib\site-packages\redis\connection.py", line 658, in read_response
    raise ConnectionError(f"Error while reading from {host_error} : {e.args}")
redis.exceptions.ConnectionError: Error while reading from 127.0.0.1:6379 : (10054, 'An existing connection was forcibly closed by the remote host', None, 10054, None)
[2025-09-04 03:51:05,354] ERROR django.request: Internal Server Error: /login
Traceback (most recent call last):
  File "C:\dev\coded\Lib\site-packages\django_redis\cache.py", line 29, in _decorator
    return method(self, *args, **kwargs)
           ^^^^^^^^^^^^^^^^^^^^^^^^^^^^^
  File "C:\dev\coded\Lib\site-packages\django_redis\cache.py", line 99, in _get
    return self.client.get(key, default=default, version=version, client=client)
           ^^^^^^^^^^^^^^^^^^^^^^^^^^^^^^^^^^^^^^^^^^^^^^^^^^^^^^^^^^^^^^^^^^^^^
  File "C:\dev\coded\Lib\site-packages\django_redis\client\default.py", line 300, in get
    raise ConnectionInterrupted(connection=client) from e
django_redis.exceptions.ConnectionInterrupted: Redis ConnectionError: Error while reading from 127.0.0.1:6379 : (10054, 'An existing connection was forcibly closed by the remote host', None, 10054, None)

During handling of the above exception, another exception occurred:

Traceback (most recent call last):
  File "C:\dev\coded\Lib\site-packages\django\core\handlers\exception.py", line 55, in inner
    response = get_response(request)
               ^^^^^^^^^^^^^^^^^^^^^
  File "C:\Users\Coded\PRO-DEV\alx-backend-security\ip_tracking\middleware.py", line 42, in __call__
    ip_data = cache.get(cache_key)
              ^^^^^^^^^^^^^^^^^^^^
  File "C:\dev\coded\Lib\site-packages\django_redis\cache.py", line 92, in get
    value = self._get(key, default, version, client)
            ^^^^^^^^^^^^^^^^^^^^^^^^^^^^^^^^^^^^^^^^
  File "C:\dev\coded\Lib\site-packages\django_redis\cache.py", line 36, in _decorator
    raise e.__cause__  # noqa: B904
    ^^^^^^^^^^^^^^^^^
  File "C:\dev\coded\Lib\site-packages\django_redis\client\default.py", line 298, in get
    value = client.get(key)
            ^^^^^^^^^^^^^^^
  File "C:\dev\coded\Lib\site-packages\redis\commands\core.py", line 1829, in get
    return self.execute_command("GET", name, keys=[name])
           ^^^^^^^^^^^^^^^^^^^^^^^^^^^^^^^^^^^^^^^^^^^^^^
  File "C:\dev\coded\Lib\site-packages\redis\client.py", line 621, in execute_command
    return self._execute_command(*args, **options)
           ^^^^^^^^^^^^^^^^^^^^^^^^^^^^^^^^^^^^^^^
  File "C:\dev\coded\Lib\site-packages\redis\client.py", line 627, in _execute_command
    conn = self.connection or pool.get_connection()
                              ^^^^^^^^^^^^^^^^^^^^^
  File "C:\dev\coded\Lib\site-packages\redis\utils.py", line 195, in wrapper
    return func(*args, **kwargs)
           ^^^^^^^^^^^^^^^^^^^^^
  File "C:\dev\coded\Lib\site-packages\redis\connection.py", line 1533, in get_connection
    connection.connect()
  File "C:\dev\coded\Lib\site-packages\redis\connection.py", line 380, in connect
    self.connect_check_health(check_health=True)
  File "C:\dev\coded\Lib\site-packages\redis\connection.py", line 403, in connect_check_health
    self.on_connect_check_health(check_health=check_health)
  File "C:\dev\coded\Lib\site-packages\redis\connection.py", line 523, in on_connect_check_health
    self.read_response()
  File "C:\dev\coded\Lib\site-packages\redis\connection.py", line 658, in read_response
    raise ConnectionError(f"Error while reading from {host_error} : {e.args}")
redis.exceptions.ConnectionError: Error while reading from 127.0.0.1:6379 : (10054, 'An existing connection was forcibly closed by the remote host', None, 10054, None)
[2025-09-04 03:51:05,354] ERROR django.request: Internal Server Error: /
Traceback (most recent call last):
  File "C:\dev\coded\Lib\site-packages\django_redis\cache.py", line 29, in _decorator
    return method(self, *args, **kwargs)
           ^^^^^^^^^^^^^^^^^^^^^^^^^^^^^
  File "C:\dev\coded\Lib\site-packages\django_redis\cache.py", line 99, in _get
    return self.client.get(key, default=default, version=version, client=client)
           ^^^^^^^^^^^^^^^^^^^^^^^^^^^^^^^^^^^^^^^^^^^^^^^^^^^^^^^^^^^^^^^^^^^^^
  File "C:\dev\coded\Lib\site-packages\django_redis\client\default.py", line 300, in get
    raise ConnectionInterrupted(connection=client) from e
django_redis.exceptions.ConnectionInterrupted: Redis ConnectionError: Error while reading from 127.0.0.1:6379 : (10054, 'An existing connection was forcibly closed by the remote host', None, 10054, None)

During handling of the above exception, another exception occurred:

Traceback (most recent call last):
  File "C:\dev\coded\Lib\site-packages\django\core\handlers\exception.py", line 55, in inner
    response = get_response(request)
               ^^^^^^^^^^^^^^^^^^^^^
  File "C:\Users\Coded\PRO-DEV\alx-backend-security\ip_tracking\middleware.py", line 42, in __call__
    ip_data = cache.get(cache_key)
              ^^^^^^^^^^^^^^^^^^^^
  File "C:\dev\coded\Lib\site-packages\django_redis\cache.py", line 92, in get
    value = self._get(key, default, version, client)
            ^^^^^^^^^^^^^^^^^^^^^^^^^^^^^^^^^^^^^^^^
  File "C:\dev\coded\Lib\site-packages\django_redis\cache.py", line 36, in _decorator
    raise e.__cause__  # noqa: B904
    ^^^^^^^^^^^^^^^^^
  File "C:\dev\coded\Lib\site-packages\django_redis\client\default.py", line 298, in get
    value = client.get(key)
            ^^^^^^^^^^^^^^^
  File "C:\dev\coded\Lib\site-packages\redis\commands\core.py", line 1829, in get
    return self.execute_command("GET", name, keys=[name])
           ^^^^^^^^^^^^^^^^^^^^^^^^^^^^^^^^^^^^^^^^^^^^^^
  File "C:\dev\coded\Lib\site-packages\redis\client.py", line 621, in execute_command
    return self._execute_command(*args, **options)
           ^^^^^^^^^^^^^^^^^^^^^^^^^^^^^^^^^^^^^^^
  File "C:\dev\coded\Lib\site-packages\redis\client.py", line 627, in _execute_command
    conn = self.connection or pool.get_connection()
                              ^^^^^^^^^^^^^^^^^^^^^
  File "C:\dev\coded\Lib\site-packages\redis\utils.py", line 195, in wrapper
    return func(*args, **kwargs)
           ^^^^^^^^^^^^^^^^^^^^^
  File "C:\dev\coded\Lib\site-packages\redis\connection.py", line 1533, in get_connection
    connection.connect()
  File "C:\dev\coded\Lib\site-packages\redis\connection.py", line 380, in connect
    self.connect_check_health(check_health=True)
  File "C:\dev\coded\Lib\site-packages\redis\connection.py", line 403, in connect_check_health
    self.on_connect_check_health(check_health=check_health)
  File "C:\dev\coded\Lib\site-packages\redis\connection.py", line 523, in on_connect_check_health
    self.read_response()
  File "C:\dev\coded\Lib\site-packages\redis\connection.py", line 658, in read_response
    raise ConnectionError(f"Error while reading from {host_error} : {e.args}")
redis.exceptions.ConnectionError: Error while reading from 127.0.0.1:6379 : (10054, 'An existing connection was forcibly closed by the remote host', None, 10054, None)
[2025-09-04 03:51:05,354] ERROR django.request: Internal Server Error: /login/
Traceback (most recent call last):
  File "C:\dev\coded\Lib\site-packages\django_redis\cache.py", line 29, in _decorator
    return method(self, *args, **kwargs)
           ^^^^^^^^^^^^^^^^^^^^^^^^^^^^^
  File "C:\dev\coded\Lib\site-packages\django_redis\cache.py", line 99, in _get
    return self.client.get(key, default=default, version=version, client=client)
           ^^^^^^^^^^^^^^^^^^^^^^^^^^^^^^^^^^^^^^^^^^^^^^^^^^^^^^^^^^^^^^^^^^^^^
  File "C:\dev\coded\Lib\site-packages\django_redis\client\default.py", line 300, in get
    raise ConnectionInterrupted(connection=client) from e
django_redis.exceptions.ConnectionInterrupted: Redis ConnectionError: Error while reading from 127.0.0.1:6379 : (10054, 'An existing connection was forcibly closed by the remote host', None, 10054, None)

During handling of the above exception, another exception occurred:

Traceback (most recent call last):
  File "C:\dev\coded\Lib\site-packages\django\core\handlers\exception.py", line 55, in inner
    response = get_response(request)
               ^^^^^^^^^^^^^^^^^^^^^
  File "C:\Users\Coded\PRO-DEV\alx-backend-security\ip_tracking\middleware.py", line 42, in __call__
    ip_data = cache.get(cache_key)
              ^^^^^^^^^^^^^^^^^^^^
  File "C:\dev\coded\Lib\site-packages\django_redis\cache.py", line 92, in get
    value = self._get(key, default, version, client)
            ^^^^^^^^^^^^^^^^^^^^^^^^^^^^^^^^^^^^^^^^
  File "C:\dev\coded\Lib\site-packages\django_redis\cache.py", line 36, in _decorator
    raise e.__cause__  # noqa: B904
    ^^^^^^^^^^^^^^^^^
  File "C:\dev\coded\Lib\site-packages\django_redis\client\default.py", line 298, in get
    value = client.get(key)
            ^^^^^^^^^^^^^^^
  File "C:\dev\coded\Lib\site-packages\redis\commands\core.py", line 1829, in get
    return self.execute_command("GET", name, keys=[name])
           ^^^^^^^^^^^^^^^^^^^^^^^^^^^^^^^^^^^^^^^^^^^^^^
  File "C:\dev\coded\Lib\site-packages\redis\client.py", line 621, in execute_command
    return self._execute_command(*args, **options)
           ^^^^^^^^^^^^^^^^^^^^^^^^^^^^^^^^^^^^^^^
  File "C:\dev\coded\Lib\site-packages\redis\client.py", line 627, in _execute_command
    conn = self.connection or pool.get_connection()
                              ^^^^^^^^^^^^^^^^^^^^^
  File "C:\dev\coded\Lib\site-packages\redis\utils.py", line 195, in wrapper
    return func(*args, **kwargs)
           ^^^^^^^^^^^^^^^^^^^^^
  File "C:\dev\coded\Lib\site-packages\redis\connection.py", line 1533, in get_connection
    connection.connect()
  File "C:\dev\coded\Lib\site-packages\redis\connection.py", line 380, in connect
    self.connect_check_health(check_health=True)
  File "C:\dev\coded\Lib\site-packages\redis\connection.py", line 403, in connect_check_health
    self.on_connect_check_health(check_health=check_health)
  File "C:\dev\coded\Lib\site-packages\redis\connection.py", line 523, in on_connect_check_health
    self.read_response()
  File "C:\dev\coded\Lib\site-packages\redis\connection.py", line 658, in read_response
    raise ConnectionError(f"Error while reading from {host_error} : {e.args}")
redis.exceptions.ConnectionError: Error while reading from 127.0.0.1:6379 : (10054, 'An existing connection was forcibly closed by the remote host', None, 10054, None)
[2025-09-04 03:51:08,016] ERROR django.request: Internal Server Error: /login/
Traceback (most recent call last):
  File "C:\dev\coded\Lib\site-packages\django_redis\cache.py", line 29, in _decorator
    return method(self, *args, **kwargs)
           ^^^^^^^^^^^^^^^^^^^^^^^^^^^^^
  File "C:\dev\coded\Lib\site-packages\django_redis\cache.py", line 99, in _get
    return self.client.get(key, default=default, version=version, client=client)
           ^^^^^^^^^^^^^^^^^^^^^^^^^^^^^^^^^^^^^^^^^^^^^^^^^^^^^^^^^^^^^^^^^^^^^
  File "C:\dev\coded\Lib\site-packages\django_redis\client\default.py", line 300, in get
    raise ConnectionInterrupted(connection=client) from e
django_redis.exceptions.ConnectionInterrupted: Redis ConnectionError: Error 10061 connecting to 127.0.0.1:6379. No connection could be made because the target machine actively refused it.

During handling of the above exception, another exception occurred:

Traceback (most recent call last):
  File "C:\dev\coded\Lib\site-packages\django\core\handlers\exception.py", line 55, in inner
    response = get_response(request)
               ^^^^^^^^^^^^^^^^^^^^^
  File "C:\Users\Coded\PRO-DEV\alx-backend-security\ip_tracking\middleware.py", line 42, in __call__
    ip_data = cache.get(cache_key)
              ^^^^^^^^^^^^^^^^^^^^
  File "C:\dev\coded\Lib\site-packages\django_redis\cache.py", line 92, in get
    value = self._get(key, default, version, client)
            ^^^^^^^^^^^^^^^^^^^^^^^^^^^^^^^^^^^^^^^^
  File "C:\dev\coded\Lib\site-packages\django_redis\cache.py", line 36, in _decorator
    raise e.__cause__  # noqa: B904
    ^^^^^^^^^^^^^^^^^
  File "C:\dev\coded\Lib\site-packages\django_redis\client\default.py", line 298, in get
    value = client.get(key)
            ^^^^^^^^^^^^^^^
  File "C:\dev\coded\Lib\site-packages\redis\commands\core.py", line 1829, in get
    return self.execute_command("GET", name, keys=[name])
           ^^^^^^^^^^^^^^^^^^^^^^^^^^^^^^^^^^^^^^^^^^^^^^
  File "C:\dev\coded\Lib\site-packages\redis\client.py", line 621, in execute_command
    return self._execute_command(*args, **options)
           ^^^^^^^^^^^^^^^^^^^^^^^^^^^^^^^^^^^^^^^
  File "C:\dev\coded\Lib\site-packages\redis\client.py", line 627, in _execute_command
    conn = self.connection or pool.get_connection()
                              ^^^^^^^^^^^^^^^^^^^^^
  File "C:\dev\coded\Lib\site-packages\redis\utils.py", line 195, in wrapper
    return func(*args, **kwargs)
           ^^^^^^^^^^^^^^^^^^^^^
  File "C:\dev\coded\Lib\site-packages\redis\connection.py", line 1533, in get_connection
    connection.connect()
  File "C:\dev\coded\Lib\site-packages\redis\connection.py", line 380, in connect
    self.connect_check_health(check_health=True)
  File "C:\dev\coded\Lib\site-packages\redis\connection.py", line 397, in connect_check_health
    raise ConnectionError(self._error_message(e))
redis.exceptions.ConnectionError: Error 10061 connecting to 127.0.0.1:6379. No connection could be made because the target machine actively refused it.
[2025-09-04 03:51:08,226] ERROR django.request: Internal Server Error: /favicon.ico
Traceback (most recent call last):
  File "C:\dev\coded\Lib\site-packages\django_redis\cache.py", line 29, in _decorator
    return method(self, *args, **kwargs)
           ^^^^^^^^^^^^^^^^^^^^^^^^^^^^^
  File "C:\dev\coded\Lib\site-packages\django_redis\cache.py", line 99, in _get
    return self.client.get(key, default=default, version=version, client=client)
           ^^^^^^^^^^^^^^^^^^^^^^^^^^^^^^^^^^^^^^^^^^^^^^^^^^^^^^^^^^^^^^^^^^^^^
  File "C:\dev\coded\Lib\site-packages\django_redis\client\default.py", line 300, in get
    raise ConnectionInterrupted(connection=client) from e
django_redis.exceptions.ConnectionInterrupted: Redis ConnectionError: Error 10061 connecting to 127.0.0.1:6379. No connection could be made because the target machine actively refused it.

During handling of the above exception, another exception occurred:

Traceback (most recent call last):
  File "C:\dev\coded\Lib\site-packages\django\core\handlers\exception.py", line 55, in inner
    response = get_response(request)
               ^^^^^^^^^^^^^^^^^^^^^
  File "C:\Users\Coded\PRO-DEV\alx-backend-security\ip_tracking\middleware.py", line 42, in __call__
    ip_data = cache.get(cache_key)
              ^^^^^^^^^^^^^^^^^^^^
  File "C:\dev\coded\Lib\site-packages\django_redis\cache.py", line 92, in get
    value = self._get(key, default, version, client)
            ^^^^^^^^^^^^^^^^^^^^^^^^^^^^^^^^^^^^^^^^
  File "C:\dev\coded\Lib\site-packages\django_redis\cache.py", line 36, in _decorator
    raise e.__cause__  # noqa: B904
    ^^^^^^^^^^^^^^^^^
  File "C:\dev\coded\Lib\site-packages\django_redis\client\default.py", line 298, in get
    value = client.get(key)
            ^^^^^^^^^^^^^^^
  File "C:\dev\coded\Lib\site-packages\redis\commands\core.py", line 1829, in get
    return self.execute_command("GET", name, keys=[name])
           ^^^^^^^^^^^^^^^^^^^^^^^^^^^^^^^^^^^^^^^^^^^^^^
  File "C:\dev\coded\Lib\site-packages\redis\client.py", line 621, in execute_command
    return self._execute_command(*args, **options)
           ^^^^^^^^^^^^^^^^^^^^^^^^^^^^^^^^^^^^^^^
  File "C:\dev\coded\Lib\site-packages\redis\client.py", line 627, in _execute_command
    conn = self.connection or pool.get_connection()
                              ^^^^^^^^^^^^^^^^^^^^^
  File "C:\dev\coded\Lib\site-packages\redis\utils.py", line 195, in wrapper
    return func(*args, **kwargs)
           ^^^^^^^^^^^^^^^^^^^^^
  File "C:\dev\coded\Lib\site-packages\redis\connection.py", line 1533, in get_connection
    connection.connect()
  File "C:\dev\coded\Lib\site-packages\redis\connection.py", line 380, in connect
    self.connect_check_health(check_health=True)
  File "C:\dev\coded\Lib\site-packages\redis\connection.py", line 397, in connect_check_health
    raise ConnectionError(self._error_message(e))
redis.exceptions.ConnectionError: Error 10061 connecting to 127.0.0.1:6379. No connection could be made because the target machine actively refused it.
[2025-09-04 03:51:10,339] ERROR django.request: Internal Server Error: /login/
Traceback (most recent call last):
  File "C:\dev\coded\Lib\site-packages\django_redis\cache.py", line 29, in _decorator
    return method(self, *args, **kwargs)
           ^^^^^^^^^^^^^^^^^^^^^^^^^^^^^
  File "C:\dev\coded\Lib\site-packages\django_redis\cache.py", line 99, in _get
    return self.client.get(key, default=default, version=version, client=client)
           ^^^^^^^^^^^^^^^^^^^^^^^^^^^^^^^^^^^^^^^^^^^^^^^^^^^^^^^^^^^^^^^^^^^^^
  File "C:\dev\coded\Lib\site-packages\django_redis\client\default.py", line 300, in get
    raise ConnectionInterrupted(connection=client) from e
django_redis.exceptions.ConnectionInterrupted: Redis ConnectionError: Error 10061 connecting to 127.0.0.1:6379. No connection could be made because the target machine actively refused it.

During handling of the above exception, another exception occurred:

Traceback (most recent call last):
  File "C:\dev\coded\Lib\site-packages\django\core\handlers\exception.py", line 55, in inner
    response = get_response(request)
               ^^^^^^^^^^^^^^^^^^^^^
  File "C:\Users\Coded\PRO-DEV\alx-backend-security\ip_tracking\middleware.py", line 42, in __call__
    ip_data = cache.get(cache_key)
              ^^^^^^^^^^^^^^^^^^^^
  File "C:\dev\coded\Lib\site-packages\django_redis\cache.py", line 92, in get
    value = self._get(key, default, version, client)
            ^^^^^^^^^^^^^^^^^^^^^^^^^^^^^^^^^^^^^^^^
  File "C:\dev\coded\Lib\site-packages\django_redis\cache.py", line 36, in _decorator
    raise e.__cause__  # noqa: B904
    ^^^^^^^^^^^^^^^^^
  File "C:\dev\coded\Lib\site-packages\django_redis\client\default.py", line 298, in get
    value = client.get(key)
            ^^^^^^^^^^^^^^^
  File "C:\dev\coded\Lib\site-packages\redis\commands\core.py", line 1829, in get
    return self.execute_command("GET", name, keys=[name])
           ^^^^^^^^^^^^^^^^^^^^^^^^^^^^^^^^^^^^^^^^^^^^^^
  File "C:\dev\coded\Lib\site-packages\redis\client.py", line 621, in execute_command
    return self._execute_command(*args, **options)
           ^^^^^^^^^^^^^^^^^^^^^^^^^^^^^^^^^^^^^^^
  File "C:\dev\coded\Lib\site-packages\redis\client.py", line 627, in _execute_command
    conn = self.connection or pool.get_connection()
                              ^^^^^^^^^^^^^^^^^^^^^
  File "C:\dev\coded\Lib\site-packages\redis\utils.py", line 195, in wrapper
    return func(*args, **kwargs)
           ^^^^^^^^^^^^^^^^^^^^^
  File "C:\dev\coded\Lib\site-packages\redis\connection.py", line 1533, in get_connection
    connection.connect()
  File "C:\dev\coded\Lib\site-packages\redis\connection.py", line 380, in connect
    self.connect_check_health(check_health=True)
  File "C:\dev\coded\Lib\site-packages\redis\connection.py", line 397, in connect_check_health
    raise ConnectionError(self._error_message(e))
redis.exceptions.ConnectionError: Error 10061 connecting to 127.0.0.1:6379. No connection could be made because the target machine actively refused it.
[2025-09-04 03:51:12,632] ERROR django.request: Internal Server Error: /login/
Traceback (most recent call last):
  File "C:\dev\coded\Lib\site-packages\django_redis\cache.py", line 29, in _decorator
    return method(self, *args, **kwargs)
           ^^^^^^^^^^^^^^^^^^^^^^^^^^^^^
  File "C:\dev\coded\Lib\site-packages\django_redis\cache.py", line 99, in _get
    return self.client.get(key, default=default, version=version, client=client)
           ^^^^^^^^^^^^^^^^^^^^^^^^^^^^^^^^^^^^^^^^^^^^^^^^^^^^^^^^^^^^^^^^^^^^^
  File "C:\dev\coded\Lib\site-packages\django_redis\client\default.py", line 300, in get
    raise ConnectionInterrupted(connection=client) from e
django_redis.exceptions.ConnectionInterrupted: Redis ConnectionError: Error 10061 connecting to 127.0.0.1:6379. No connection could be made because the target machine actively refused it.

During handling of the above exception, another exception occurred:

Traceback (most recent call last):
  File "C:\dev\coded\Lib\site-packages\django\core\handlers\exception.py", line 55, in inner
    response = get_response(request)
               ^^^^^^^^^^^^^^^^^^^^^
  File "C:\Users\Coded\PRO-DEV\alx-backend-security\ip_tracking\middleware.py", line 42, in __call__
    ip_data = cache.get(cache_key)
              ^^^^^^^^^^^^^^^^^^^^
  File "C:\dev\coded\Lib\site-packages\django_redis\cache.py", line 92, in get
    value = self._get(key, default, version, client)
            ^^^^^^^^^^^^^^^^^^^^^^^^^^^^^^^^^^^^^^^^
  File "C:\dev\coded\Lib\site-packages\django_redis\cache.py", line 36, in _decorator
    raise e.__cause__  # noqa: B904
    ^^^^^^^^^^^^^^^^^
  File "C:\dev\coded\Lib\site-packages\django_redis\client\default.py", line 298, in get
    value = client.get(key)
            ^^^^^^^^^^^^^^^
  File "C:\dev\coded\Lib\site-packages\redis\commands\core.py", line 1829, in get
    return self.execute_command("GET", name, keys=[name])
           ^^^^^^^^^^^^^^^^^^^^^^^^^^^^^^^^^^^^^^^^^^^^^^
  File "C:\dev\coded\Lib\site-packages\redis\client.py", line 621, in execute_command
    return self._execute_command(*args, **options)
           ^^^^^^^^^^^^^^^^^^^^^^^^^^^^^^^^^^^^^^^
  File "C:\dev\coded\Lib\site-packages\redis\client.py", line 627, in _execute_command
    conn = self.connection or pool.get_connection()
                              ^^^^^^^^^^^^^^^^^^^^^
  File "C:\dev\coded\Lib\site-packages\redis\utils.py", line 195, in wrapper
    return func(*args, **kwargs)
           ^^^^^^^^^^^^^^^^^^^^^
  File "C:\dev\coded\Lib\site-packages\redis\connection.py", line 1533, in get_connection
    connection.connect()
  File "C:\dev\coded\Lib\site-packages\redis\connection.py", line 380, in connect
    self.connect_check_health(check_health=True)
  File "C:\dev\coded\Lib\site-packages\redis\connection.py", line 397, in connect_check_health
    raise ConnectionError(self._error_message(e))
redis.exceptions.ConnectionError: Error 10061 connecting to 127.0.0.1:6379. No connection could be made because the target machine actively refused it.
[2025-09-04 03:51:14,923] ERROR django.request: Internal Server Error: /login/
Traceback (most recent call last):
  File "C:\dev\coded\Lib\site-packages\django_redis\cache.py", line 29, in _decorator
    return method(self, *args, **kwargs)
           ^^^^^^^^^^^^^^^^^^^^^^^^^^^^^
  File "C:\dev\coded\Lib\site-packages\django_redis\cache.py", line 99, in _get
    return self.client.get(key, default=default, version=version, client=client)
           ^^^^^^^^^^^^^^^^^^^^^^^^^^^^^^^^^^^^^^^^^^^^^^^^^^^^^^^^^^^^^^^^^^^^^
  File "C:\dev\coded\Lib\site-packages\django_redis\client\default.py", line 300, in get
    raise ConnectionInterrupted(connection=client) from e
django_redis.exceptions.ConnectionInterrupted: Redis ConnectionError: Error 10061 connecting to 127.0.0.1:6379. No connection could be made because the target machine actively refused it.

During handling of the above exception, another exception occurred:

Traceback (most recent call last):
  File "C:\dev\coded\Lib\site-packages\django\core\handlers\exception.py", line 55, in inner
    response = get_response(request)
               ^^^^^^^^^^^^^^^^^^^^^
  File "C:\Users\Coded\PRO-DEV\alx-backend-security\ip_tracking\middleware.py", line 42, in __call__
    ip_data = cache.get(cache_key)
              ^^^^^^^^^^^^^^^^^^^^
  File "C:\dev\coded\Lib\site-packages\django_redis\cache.py", line 92, in get
    value = self._get(key, default, version, client)
            ^^^^^^^^^^^^^^^^^^^^^^^^^^^^^^^^^^^^^^^^
  File "C:\dev\coded\Lib\site-packages\django_redis\cache.py", line 36, in _decorator
    raise e.__cause__  # noqa: B904
    ^^^^^^^^^^^^^^^^^
  File "C:\dev\coded\Lib\site-packages\django_redis\client\default.py", line 298, in get
    value = client.get(key)
            ^^^^^^^^^^^^^^^
  File "C:\dev\coded\Lib\site-packages\redis\commands\core.py", line 1829, in get
    return self.execute_command("GET", name, keys=[name])
           ^^^^^^^^^^^^^^^^^^^^^^^^^^^^^^^^^^^^^^^^^^^^^^
  File "C:\dev\coded\Lib\site-packages\redis\client.py", line 621, in execute_command
    return self._execute_command(*args, **options)
           ^^^^^^^^^^^^^^^^^^^^^^^^^^^^^^^^^^^^^^^
  File "C:\dev\coded\Lib\site-packages\redis\client.py", line 627, in _execute_command
    conn = self.connection or pool.get_connection()
                              ^^^^^^^^^^^^^^^^^^^^^
  File "C:\dev\coded\Lib\site-packages\redis\utils.py", line 195, in wrapper
    return func(*args, **kwargs)
           ^^^^^^^^^^^^^^^^^^^^^
  File "C:\dev\coded\Lib\site-packages\redis\connection.py", line 1533, in get_connection
    connection.connect()
  File "C:\dev\coded\Lib\site-packages\redis\connection.py", line 380, in connect
    self.connect_check_health(check_health=True)
  File "C:\dev\coded\Lib\site-packages\redis\connection.py", line 397, in connect_check_health
    raise ConnectionError(self._error_message(e))
redis.exceptions.ConnectionError: Error 10061 connecting to 127.0.0.1:6379. No connection could be made because the target machine actively refused it.
[2025-09-04 03:51:17,274] ERROR django.request: Internal Server Error: /login/
Traceback (most recent call last):
  File "C:\dev\coded\Lib\site-packages\django_redis\cache.py", line 29, in _decorator
    return method(self, *args, **kwargs)
           ^^^^^^^^^^^^^^^^^^^^^^^^^^^^^
  File "C:\dev\coded\Lib\site-packages\django_redis\cache.py", line 99, in _get
    return self.client.get(key, default=default, version=version, client=client)
           ^^^^^^^^^^^^^^^^^^^^^^^^^^^^^^^^^^^^^^^^^^^^^^^^^^^^^^^^^^^^^^^^^^^^^
  File "C:\dev\coded\Lib\site-packages\django_redis\client\default.py", line 300, in get
    raise ConnectionInterrupted(connection=client) from e
django_redis.exceptions.ConnectionInterrupted: Redis ConnectionError: Error 10061 connecting to 127.0.0.1:6379. No connection could be made because the target machine actively refused it.

During handling of the above exception, another exception occurred:

Traceback (most recent call last):
  File "C:\dev\coded\Lib\site-packages\django\core\handlers\exception.py", line 55, in inner
    response = get_response(request)
               ^^^^^^^^^^^^^^^^^^^^^
  File "C:\Users\Coded\PRO-DEV\alx-backend-security\ip_tracking\middleware.py", line 42, in __call__
    ip_data = cache.get(cache_key)
              ^^^^^^^^^^^^^^^^^^^^
  File "C:\dev\coded\Lib\site-packages\django_redis\cache.py", line 92, in get
    value = self._get(key, default, version, client)
            ^^^^^^^^^^^^^^^^^^^^^^^^^^^^^^^^^^^^^^^^
  File "C:\dev\coded\Lib\site-packages\django_redis\cache.py", line 36, in _decorator
    raise e.__cause__  # noqa: B904
    ^^^^^^^^^^^^^^^^^
  File "C:\dev\coded\Lib\site-packages\django_redis\client\default.py", line 298, in get
    value = client.get(key)
            ^^^^^^^^^^^^^^^
  File "C:\dev\coded\Lib\site-packages\redis\commands\core.py", line 1829, in get
    return self.execute_command("GET", name, keys=[name])
           ^^^^^^^^^^^^^^^^^^^^^^^^^^^^^^^^^^^^^^^^^^^^^^
  File "C:\dev\coded\Lib\site-packages\redis\client.py", line 621, in execute_command
    return self._execute_command(*args, **options)
           ^^^^^^^^^^^^^^^^^^^^^^^^^^^^^^^^^^^^^^^
  File "C:\dev\coded\Lib\site-packages\redis\client.py", line 627, in _execute_command
    conn = self.connection or pool.get_connection()
                              ^^^^^^^^^^^^^^^^^^^^^
  File "C:\dev\coded\Lib\site-packages\redis\utils.py", line 195, in wrapper
    return func(*args, **kwargs)
           ^^^^^^^^^^^^^^^^^^^^^
  File "C:\dev\coded\Lib\site-packages\redis\connection.py", line 1533, in get_connection
    connection.connect()
  File "C:\dev\coded\Lib\site-packages\redis\connection.py", line 380, in connect
    self.connect_check_health(check_health=True)
  File "C:\dev\coded\Lib\site-packages\redis\connection.py", line 397, in connect_check_health
    raise ConnectionError(self._error_message(e))
redis.exceptions.ConnectionError: Error 10061 connecting to 127.0.0.1:6379. No connection could be made because the target machine actively refused it.
[2025-09-04 03:51:19,673] ERROR django.request: Internal Server Error: /login/
Traceback (most recent call last):
  File "C:\dev\coded\Lib\site-packages\django_redis\cache.py", line 29, in _decorator
    return method(self, *args, **kwargs)
           ^^^^^^^^^^^^^^^^^^^^^^^^^^^^^
  File "C:\dev\coded\Lib\site-packages\django_redis\cache.py", line 99, in _get
    return self.client.get(key, default=default, version=version, client=client)
           ^^^^^^^^^^^^^^^^^^^^^^^^^^^^^^^^^^^^^^^^^^^^^^^^^^^^^^^^^^^^^^^^^^^^^
  File "C:\dev\coded\Lib\site-packages\django_redis\client\default.py", line 300, in get
    raise ConnectionInterrupted(connection=client) from e
django_redis.exceptions.ConnectionInterrupted: Redis ConnectionError: Error 10061 connecting to 127.0.0.1:6379. No connection could be made because the target machine actively refused it.

During handling of the above exception, another exception occurred:

Traceback (most recent call last):
  File "C:\dev\coded\Lib\site-packages\django\core\handlers\exception.py", line 55, in inner
    response = get_response(request)
               ^^^^^^^^^^^^^^^^^^^^^
  File "C:\Users\Coded\PRO-DEV\alx-backend-security\ip_tracking\middleware.py", line 42, in __call__
    ip_data = cache.get(cache_key)
              ^^^^^^^^^^^^^^^^^^^^
  File "C:\dev\coded\Lib\site-packages\django_redis\cache.py", line 92, in get
    value = self._get(key, default, version, client)
            ^^^^^^^^^^^^^^^^^^^^^^^^^^^^^^^^^^^^^^^^
  File "C:\dev\coded\Lib\site-packages\django_redis\cache.py", line 36, in _decorator
    raise e.__cause__  # noqa: B904
    ^^^^^^^^^^^^^^^^^
  File "C:\dev\coded\Lib\site-packages\django_redis\client\default.py", line 298, in get
    value = client.get(key)
            ^^^^^^^^^^^^^^^
  File "C:\dev\coded\Lib\site-packages\redis\commands\core.py", line 1829, in get
    return self.execute_command("GET", name, keys=[name])
           ^^^^^^^^^^^^^^^^^^^^^^^^^^^^^^^^^^^^^^^^^^^^^^
  File "C:\dev\coded\Lib\site-packages\redis\client.py", line 621, in execute_command
    return self._execute_command(*args, **options)
           ^^^^^^^^^^^^^^^^^^^^^^^^^^^^^^^^^^^^^^^
  File "C:\dev\coded\Lib\site-packages\redis\client.py", line 627, in _execute_command
    conn = self.connection or pool.get_connection()
                              ^^^^^^^^^^^^^^^^^^^^^
  File "C:\dev\coded\Lib\site-packages\redis\utils.py", line 195, in wrapper
    return func(*args, **kwargs)
           ^^^^^^^^^^^^^^^^^^^^^
  File "C:\dev\coded\Lib\site-packages\redis\connection.py", line 1533, in get_connection
    connection.connect()
  File "C:\dev\coded\Lib\site-packages\redis\connection.py", line 380, in connect
    self.connect_check_health(check_health=True)
  File "C:\dev\coded\Lib\site-packages\redis\connection.py", line 397, in connect_check_health
    raise ConnectionError(self._error_message(e))
redis.exceptions.ConnectionError: Error 10061 connecting to 127.0.0.1:6379. No connection could be made because the target machine actively refused it.
[2025-09-04 03:54:27,410] INFO django.utils.autoreload: Watching for file changes with StatReloader
[2025-09-04 03:55:48,356] INFO ip_tracking.middleware: [127.0.0.1] (None, None) -> /login/ | Count: 1
[2025-09-04 03:56:24,655] INFO ip_tracking.middleware: [127.0.0.1] (None, None) -> / | Count: 2
[2025-09-04 03:56:24,658] WARNING django.request: Not Found: /
[2025-09-04 03:56:25,178] INFO ip_tracking.middleware: [127.0.0.1] (None, None) -> /favicon.ico | Count: 3
[2025-09-04 03:56:25,179] WARNING django.request: Not Found: /favicon.ico
[2025-09-04 03:56:29,948] INFO ip_tracking.middleware: [127.0.0.1] (None, None) -> /login/ | Count: 4
[2025-09-04 03:56:50,140] INFO ip_tracking.middleware: [127.0.0.1] (None, None) -> / | Count: 5
[2025-09-04 03:56:50,140] WARNING django.request: Not Found: /
[2025-09-04 03:56:53,213] INFO ip_tracking.middleware: [127.0.0.1] (None, None) -> /login/ | Count: 6
[2025-09-04 03:56:54,410] INFO ip_tracking.middleware: [127.0.0.1] (None, None) -> /login/ | Count: 7
[2025-09-04 03:56:55,678] INFO ip_tracking.middleware: [127.0.0.1] (None, None) -> /login/ | Count: 8
[2025-09-04 03:56:56,580] INFO ip_tracking.middleware: [127.0.0.1] (None, None) -> /login/ | Count: 9
[2025-09-04 03:56:56,827] INFO ip_tracking.middleware: [127.0.0.1] (None, None) -> /login/ | Count: 10
[2025-09-04 03:56:57,012] INFO ip_tracking.middleware: [127.0.0.1] (None, None) -> /login/ | Count: 11
[2025-09-04 03:56:57,230] INFO ip_tracking.middleware: [127.0.0.1] (None, None) -> /login/ | Count: 12
[2025-09-04 03:56:57,414] INFO ip_tracking.middleware: [127.0.0.1] (None, None) -> /login/ | Count: 13
[2025-09-04 03:56:57,591] INFO ip_tracking.middleware: [127.0.0.1] (None, None) -> /login/ | Count: 14
[2025-09-04 03:56:57,759] INFO ip_tracking.middleware: [127.0.0.1] (None, None) -> /login/ | Count: 15
[2025-09-04 03:56:57,988] INFO ip_tracking.middleware: [127.0.0.1] (None, None) -> /login/ | Count: 16
[2025-09-04 03:56:58,209] INFO ip_tracking.middleware: [127.0.0.1] (None, None) -> /login/ | Count: 17
[2025-09-04 03:56:58,425] INFO ip_tracking.middleware: [127.0.0.1] (None, None) -> /login/ | Count: 18
[2025-09-04 03:56:58,643] INFO ip_tracking.middleware: [127.0.0.1] (None, None) -> /login/ | Count: 19
[2025-09-04 03:56:58,876] INFO ip_tracking.middleware: [127.0.0.1] (None, None) -> /login/ | Count: 20
[2025-09-04 03:57:01,358] INFO ip_tracking.middleware: [127.0.0.1] (None, None) -> /login/ | Count: 21
[2025-09-04 03:58:24,786] ERROR django.request: Internal Server Error: /login/
Traceback (most recent call last):
  File "C:\dev\coded\Lib\site-packages\django_redis\cache.py", line 29, in _decorator
    return method(self, *args, **kwargs)
           ^^^^^^^^^^^^^^^^^^^^^^^^^^^^^
  File "C:\dev\coded\Lib\site-packages\django_redis\cache.py", line 81, in set
    return self.client.set(*args, **kwargs)
           ^^^^^^^^^^^^^^^^^^^^^^^^^^^^^^^^
  File "C:\dev\coded\Lib\site-packages\django_redis\client\default.py", line 224, in set
    raise ConnectionInterrupted(connection=client) from e
django_redis.exceptions.ConnectionInterrupted: Redis ResponseError: MISCONF Redis is configured to save RDB snapshots, but it is currently not able to persist on disk. Commands that may modify the data set are disabled, because this instance is configured to report errors during writes if RDB snapshotting fails (stop-writes-on-bgsave-error option). Please check the Redis logs for details about the RDB error.

During handling of the above exception, another exception occurred:

Traceback (most recent call last):
  File "C:\dev\coded\Lib\site-packages\django\core\handlers\exception.py", line 55, in inner
    response = get_response(request)
               ^^^^^^^^^^^^^^^^^^^^^
  File "C:\Users\Coded\PRO-DEV\alx-backend-security\ip_tracking\middleware.py", line 50, in __call__
    cache.set(cache_key, ip_data, timeout=3600)  # 1h
    ^^^^^^^^^^^^^^^^^^^^^^^^^^^^^^^^^^^^^^^^^^^
  File "C:\dev\coded\Lib\site-packages\django_redis\cache.py", line 36, in _decorator
    raise e.__cause__  # noqa: B904
    ^^^^^^^^^^^^^^^^^
  File "C:\dev\coded\Lib\site-packages\django_redis\client\default.py", line 214, in set
    return bool(client.set(nkey, nvalue, nx=nx, px=timeout, xx=xx))
                ^^^^^^^^^^^^^^^^^^^^^^^^^^^^^^^^^^^^^^^^^^^^^^^^^^
  File "C:\dev\coded\Lib\site-packages\redis\commands\core.py", line 2305, in set
    return self.execute_command("SET", *pieces, **options)
           ^^^^^^^^^^^^^^^^^^^^^^^^^^^^^^^^^^^^^^^^^^^^^^^
  File "C:\dev\coded\Lib\site-packages\redis\client.py", line 621, in execute_command
    return self._execute_command(*args, **options)
           ^^^^^^^^^^^^^^^^^^^^^^^^^^^^^^^^^^^^^^^
  File "C:\dev\coded\Lib\site-packages\redis\client.py", line 632, in _execute_command
    return conn.retry.call_with_retry(
           ^^^^^^^^^^^^^^^^^^^^^^^^^^^
  File "C:\dev\coded\Lib\site-packages\redis\retry.py", line 105, in call_with_retry
    return do()
           ^^^^
  File "C:\dev\coded\Lib\site-packages\redis\client.py", line 633, in <lambda>
    lambda: self._send_command_parse_response(
            ^^^^^^^^^^^^^^^^^^^^^^^^^^^^^^^^^^
  File "C:\dev\coded\Lib\site-packages\redis\client.py", line 604, in _send_command_parse_response
    return self.parse_response(conn, command_name, **options)
           ^^^^^^^^^^^^^^^^^^^^^^^^^^^^^^^^^^^^^^^^^^^^^^^^^^
  File "C:\dev\coded\Lib\site-packages\redis\client.py", line 651, in parse_response
    response = connection.read_response()
               ^^^^^^^^^^^^^^^^^^^^^^^^^^
  File "C:\dev\coded\Lib\site-packages\redis\connection.py", line 672, in read_response
    raise response
redis.exceptions.ResponseError: MISCONF Redis is configured to save RDB snapshots, but it is currently not able to persist on disk. Commands that may modify the data set are disabled, because this instance is configured to report errors during writes if RDB snapshotting fails (stop-writes-on-bgsave-error option). Please check the Redis logs for details about the RDB error.
[2025-09-04 03:58:25,863] ERROR django.request: Internal Server Error: /login/
Traceback (most recent call last):
  File "C:\dev\coded\Lib\site-packages\django_redis\cache.py", line 29, in _decorator
    return method(self, *args, **kwargs)
           ^^^^^^^^^^^^^^^^^^^^^^^^^^^^^
  File "C:\dev\coded\Lib\site-packages\django_redis\cache.py", line 81, in set
    return self.client.set(*args, **kwargs)
           ^^^^^^^^^^^^^^^^^^^^^^^^^^^^^^^^
  File "C:\dev\coded\Lib\site-packages\django_redis\client\default.py", line 224, in set
    raise ConnectionInterrupted(connection=client) from e
django_redis.exceptions.ConnectionInterrupted: Redis ResponseError: MISCONF Redis is configured to save RDB snapshots, but it is currently not able to persist on disk. Commands that may modify the data set are disabled, because this instance is configured to report errors during writes if RDB snapshotting fails (stop-writes-on-bgsave-error option). Please check the Redis logs for details about the RDB error.

During handling of the above exception, another exception occurred:

Traceback (most recent call last):
  File "C:\dev\coded\Lib\site-packages\django\core\handlers\exception.py", line 55, in inner
    response = get_response(request)
               ^^^^^^^^^^^^^^^^^^^^^
  File "C:\Users\Coded\PRO-DEV\alx-backend-security\ip_tracking\middleware.py", line 50, in __call__
    cache.set(cache_key, ip_data, timeout=3600)  # 1h
    ^^^^^^^^^^^^^^^^^^^^^^^^^^^^^^^^^^^^^^^^^^^
  File "C:\dev\coded\Lib\site-packages\django_redis\cache.py", line 36, in _decorator
    raise e.__cause__  # noqa: B904
    ^^^^^^^^^^^^^^^^^
  File "C:\dev\coded\Lib\site-packages\django_redis\client\default.py", line 214, in set
    return bool(client.set(nkey, nvalue, nx=nx, px=timeout, xx=xx))
                ^^^^^^^^^^^^^^^^^^^^^^^^^^^^^^^^^^^^^^^^^^^^^^^^^^
  File "C:\dev\coded\Lib\site-packages\redis\commands\core.py", line 2305, in set
    return self.execute_command("SET", *pieces, **options)
           ^^^^^^^^^^^^^^^^^^^^^^^^^^^^^^^^^^^^^^^^^^^^^^^
  File "C:\dev\coded\Lib\site-packages\redis\client.py", line 621, in execute_command
    return self._execute_command(*args, **options)
           ^^^^^^^^^^^^^^^^^^^^^^^^^^^^^^^^^^^^^^^
  File "C:\dev\coded\Lib\site-packages\redis\client.py", line 632, in _execute_command
    return conn.retry.call_with_retry(
           ^^^^^^^^^^^^^^^^^^^^^^^^^^^
  File "C:\dev\coded\Lib\site-packages\redis\retry.py", line 105, in call_with_retry
    return do()
           ^^^^
  File "C:\dev\coded\Lib\site-packages\redis\client.py", line 633, in <lambda>
    lambda: self._send_command_parse_response(
            ^^^^^^^^^^^^^^^^^^^^^^^^^^^^^^^^^^
  File "C:\dev\coded\Lib\site-packages\redis\client.py", line 604, in _send_command_parse_response
    return self.parse_response(conn, command_name, **options)
           ^^^^^^^^^^^^^^^^^^^^^^^^^^^^^^^^^^^^^^^^^^^^^^^^^^
  File "C:\dev\coded\Lib\site-packages\redis\client.py", line 651, in parse_response
    response = connection.read_response()
               ^^^^^^^^^^^^^^^^^^^^^^^^^^
  File "C:\dev\coded\Lib\site-packages\redis\connection.py", line 672, in read_response
    raise response
redis.exceptions.ResponseError: MISCONF Redis is configured to save RDB snapshots, but it is currently not able to persist on disk. Commands that may modify the data set are disabled, because this instance is configured to report errors during writes if RDB snapshotting fails (stop-writes-on-bgsave-error option). Please check the Redis logs for details about the RDB error.
[2025-09-04 03:58:26,957] ERROR django.request: Internal Server Error: /login/
Traceback (most recent call last):
  File "C:\dev\coded\Lib\site-packages\django_redis\cache.py", line 29, in _decorator
    return method(self, *args, **kwargs)
           ^^^^^^^^^^^^^^^^^^^^^^^^^^^^^
  File "C:\dev\coded\Lib\site-packages\django_redis\cache.py", line 81, in set
    return self.client.set(*args, **kwargs)
           ^^^^^^^^^^^^^^^^^^^^^^^^^^^^^^^^
  File "C:\dev\coded\Lib\site-packages\django_redis\client\default.py", line 224, in set
    raise ConnectionInterrupted(connection=client) from e
django_redis.exceptions.ConnectionInterrupted: Redis ResponseError: MISCONF Redis is configured to save RDB snapshots, but it is currently not able to persist on disk. Commands that may modify the data set are disabled, because this instance is configured to report errors during writes if RDB snapshotting fails (stop-writes-on-bgsave-error option). Please check the Redis logs for details about the RDB error.

During handling of the above exception, another exception occurred:

Traceback (most recent call last):
  File "C:\dev\coded\Lib\site-packages\django\core\handlers\exception.py", line 55, in inner
    response = get_response(request)
               ^^^^^^^^^^^^^^^^^^^^^
  File "C:\Users\Coded\PRO-DEV\alx-backend-security\ip_tracking\middleware.py", line 50, in __call__
    cache.set(cache_key, ip_data, timeout=3600)  # 1h
    ^^^^^^^^^^^^^^^^^^^^^^^^^^^^^^^^^^^^^^^^^^^
  File "C:\dev\coded\Lib\site-packages\django_redis\cache.py", line 36, in _decorator
    raise e.__cause__  # noqa: B904
    ^^^^^^^^^^^^^^^^^
  File "C:\dev\coded\Lib\site-packages\django_redis\client\default.py", line 214, in set
    return bool(client.set(nkey, nvalue, nx=nx, px=timeout, xx=xx))
                ^^^^^^^^^^^^^^^^^^^^^^^^^^^^^^^^^^^^^^^^^^^^^^^^^^
  File "C:\dev\coded\Lib\site-packages\redis\commands\core.py", line 2305, in set
    return self.execute_command("SET", *pieces, **options)
           ^^^^^^^^^^^^^^^^^^^^^^^^^^^^^^^^^^^^^^^^^^^^^^^
  File "C:\dev\coded\Lib\site-packages\redis\client.py", line 621, in execute_command
    return self._execute_command(*args, **options)
           ^^^^^^^^^^^^^^^^^^^^^^^^^^^^^^^^^^^^^^^
  File "C:\dev\coded\Lib\site-packages\redis\client.py", line 632, in _execute_command
    return conn.retry.call_with_retry(
           ^^^^^^^^^^^^^^^^^^^^^^^^^^^
  File "C:\dev\coded\Lib\site-packages\redis\retry.py", line 105, in call_with_retry
    return do()
           ^^^^
  File "C:\dev\coded\Lib\site-packages\redis\client.py", line 633, in <lambda>
    lambda: self._send_command_parse_response(
            ^^^^^^^^^^^^^^^^^^^^^^^^^^^^^^^^^^
  File "C:\dev\coded\Lib\site-packages\redis\client.py", line 604, in _send_command_parse_response
    return self.parse_response(conn, command_name, **options)
           ^^^^^^^^^^^^^^^^^^^^^^^^^^^^^^^^^^^^^^^^^^^^^^^^^^
  File "C:\dev\coded\Lib\site-packages\redis\client.py", line 651, in parse_response
    response = connection.read_response()
               ^^^^^^^^^^^^^^^^^^^^^^^^^^
  File "C:\dev\coded\Lib\site-packages\redis\connection.py", line 672, in read_response
    raise response
redis.exceptions.ResponseError: MISCONF Redis is configured to save RDB snapshots, but it is currently not able to persist on disk. Commands that may modify the data set are disabled, because this instance is configured to report errors during writes if RDB snapshotting fails (stop-writes-on-bgsave-error option). Please check the Redis logs for details about the RDB error.
[2025-09-04 03:58:28,030] ERROR django.request: Internal Server Error: /login/
Traceback (most recent call last):
  File "C:\dev\coded\Lib\site-packages\django_redis\cache.py", line 29, in _decorator
    return method(self, *args, **kwargs)
           ^^^^^^^^^^^^^^^^^^^^^^^^^^^^^
  File "C:\dev\coded\Lib\site-packages\django_redis\cache.py", line 81, in set
    return self.client.set(*args, **kwargs)
           ^^^^^^^^^^^^^^^^^^^^^^^^^^^^^^^^
  File "C:\dev\coded\Lib\site-packages\django_redis\client\default.py", line 224, in set
    raise ConnectionInterrupted(connection=client) from e
django_redis.exceptions.ConnectionInterrupted: Redis ResponseError: MISCONF Redis is configured to save RDB snapshots, but it is currently not able to persist on disk. Commands that may modify the data set are disabled, because this instance is configured to report errors during writes if RDB snapshotting fails (stop-writes-on-bgsave-error option). Please check the Redis logs for details about the RDB error.

During handling of the above exception, another exception occurred:

Traceback (most recent call last):
  File "C:\dev\coded\Lib\site-packages\django\core\handlers\exception.py", line 55, in inner
    response = get_response(request)
               ^^^^^^^^^^^^^^^^^^^^^
  File "C:\Users\Coded\PRO-DEV\alx-backend-security\ip_tracking\middleware.py", line 50, in __call__
    cache.set(cache_key, ip_data, timeout=3600)  # 1h
    ^^^^^^^^^^^^^^^^^^^^^^^^^^^^^^^^^^^^^^^^^^^
  File "C:\dev\coded\Lib\site-packages\django_redis\cache.py", line 36, in _decorator
    raise e.__cause__  # noqa: B904
    ^^^^^^^^^^^^^^^^^
  File "C:\dev\coded\Lib\site-packages\django_redis\client\default.py", line 214, in set
    return bool(client.set(nkey, nvalue, nx=nx, px=timeout, xx=xx))
                ^^^^^^^^^^^^^^^^^^^^^^^^^^^^^^^^^^^^^^^^^^^^^^^^^^
  File "C:\dev\coded\Lib\site-packages\redis\commands\core.py", line 2305, in set
    return self.execute_command("SET", *pieces, **options)
           ^^^^^^^^^^^^^^^^^^^^^^^^^^^^^^^^^^^^^^^^^^^^^^^
  File "C:\dev\coded\Lib\site-packages\redis\client.py", line 621, in execute_command
    return self._execute_command(*args, **options)
           ^^^^^^^^^^^^^^^^^^^^^^^^^^^^^^^^^^^^^^^
  File "C:\dev\coded\Lib\site-packages\redis\client.py", line 632, in _execute_command
    return conn.retry.call_with_retry(
           ^^^^^^^^^^^^^^^^^^^^^^^^^^^
  File "C:\dev\coded\Lib\site-packages\redis\retry.py", line 105, in call_with_retry
    return do()
           ^^^^
  File "C:\dev\coded\Lib\site-packages\redis\client.py", line 633, in <lambda>
    lambda: self._send_command_parse_response(
            ^^^^^^^^^^^^^^^^^^^^^^^^^^^^^^^^^^
  File "C:\dev\coded\Lib\site-packages\redis\client.py", line 604, in _send_command_parse_response
    return self.parse_response(conn, command_name, **options)
           ^^^^^^^^^^^^^^^^^^^^^^^^^^^^^^^^^^^^^^^^^^^^^^^^^^
  File "C:\dev\coded\Lib\site-packages\redis\client.py", line 651, in parse_response
    response = connection.read_response()
               ^^^^^^^^^^^^^^^^^^^^^^^^^^
  File "C:\dev\coded\Lib\site-packages\redis\connection.py", line 672, in read_response
    raise response
redis.exceptions.ResponseError: MISCONF Redis is configured to save RDB snapshots, but it is currently not able to persist on disk. Commands that may modify the data set are disabled, because this instance is configured to report errors during writes if RDB snapshotting fails (stop-writes-on-bgsave-error option). Please check the Redis logs for details about the RDB error.
[2025-09-04 03:58:29,105] ERROR django.request: Internal Server Error: /login/
Traceback (most recent call last):
  File "C:\dev\coded\Lib\site-packages\django_redis\cache.py", line 29, in _decorator
    return method(self, *args, **kwargs)
           ^^^^^^^^^^^^^^^^^^^^^^^^^^^^^
  File "C:\dev\coded\Lib\site-packages\django_redis\cache.py", line 81, in set
    return self.client.set(*args, **kwargs)
           ^^^^^^^^^^^^^^^^^^^^^^^^^^^^^^^^
  File "C:\dev\coded\Lib\site-packages\django_redis\client\default.py", line 224, in set
    raise ConnectionInterrupted(connection=client) from e
django_redis.exceptions.ConnectionInterrupted: Redis ResponseError: MISCONF Redis is configured to save RDB snapshots, but it is currently not able to persist on disk. Commands that may modify the data set are disabled, because this instance is configured to report errors during writes if RDB snapshotting fails (stop-writes-on-bgsave-error option). Please check the Redis logs for details about the RDB error.

During handling of the above exception, another exception occurred:

Traceback (most recent call last):
  File "C:\dev\coded\Lib\site-packages\django\core\handlers\exception.py", line 55, in inner
    response = get_response(request)
               ^^^^^^^^^^^^^^^^^^^^^
  File "C:\Users\Coded\PRO-DEV\alx-backend-security\ip_tracking\middleware.py", line 50, in __call__
    cache.set(cache_key, ip_data, timeout=3600)  # 1h
    ^^^^^^^^^^^^^^^^^^^^^^^^^^^^^^^^^^^^^^^^^^^
  File "C:\dev\coded\Lib\site-packages\django_redis\cache.py", line 36, in _decorator
    raise e.__cause__  # noqa: B904
    ^^^^^^^^^^^^^^^^^
  File "C:\dev\coded\Lib\site-packages\django_redis\client\default.py", line 214, in set
    return bool(client.set(nkey, nvalue, nx=nx, px=timeout, xx=xx))
                ^^^^^^^^^^^^^^^^^^^^^^^^^^^^^^^^^^^^^^^^^^^^^^^^^^
  File "C:\dev\coded\Lib\site-packages\redis\commands\core.py", line 2305, in set
    return self.execute_command("SET", *pieces, **options)
           ^^^^^^^^^^^^^^^^^^^^^^^^^^^^^^^^^^^^^^^^^^^^^^^
  File "C:\dev\coded\Lib\site-packages\redis\client.py", line 621, in execute_command
    return self._execute_command(*args, **options)
           ^^^^^^^^^^^^^^^^^^^^^^^^^^^^^^^^^^^^^^^
  File "C:\dev\coded\Lib\site-packages\redis\client.py", line 632, in _execute_command
    return conn.retry.call_with_retry(
           ^^^^^^^^^^^^^^^^^^^^^^^^^^^
  File "C:\dev\coded\Lib\site-packages\redis\retry.py", line 105, in call_with_retry
    return do()
           ^^^^
  File "C:\dev\coded\Lib\site-packages\redis\client.py", line 633, in <lambda>
    lambda: self._send_command_parse_response(
            ^^^^^^^^^^^^^^^^^^^^^^^^^^^^^^^^^^
  File "C:\dev\coded\Lib\site-packages\redis\client.py", line 604, in _send_command_parse_response
    return self.parse_response(conn, command_name, **options)
           ^^^^^^^^^^^^^^^^^^^^^^^^^^^^^^^^^^^^^^^^^^^^^^^^^^
  File "C:\dev\coded\Lib\site-packages\redis\client.py", line 651, in parse_response
    response = connection.read_response()
               ^^^^^^^^^^^^^^^^^^^^^^^^^^
  File "C:\dev\coded\Lib\site-packages\redis\connection.py", line 672, in read_response
    raise response
redis.exceptions.ResponseError: MISCONF Redis is configured to save RDB snapshots, but it is currently not able to persist on disk. Commands that may modify the data set are disabled, because this instance is configured to report errors during writes if RDB snapshotting fails (stop-writes-on-bgsave-error option). Please check the Redis logs for details about the RDB error.
[2025-09-04 03:58:30,200] ERROR django.request: Internal Server Error: /login/
Traceback (most recent call last):
  File "C:\dev\coded\Lib\site-packages\django_redis\cache.py", line 29, in _decorator
    return method(self, *args, **kwargs)
           ^^^^^^^^^^^^^^^^^^^^^^^^^^^^^
  File "C:\dev\coded\Lib\site-packages\django_redis\cache.py", line 81, in set
    return self.client.set(*args, **kwargs)
           ^^^^^^^^^^^^^^^^^^^^^^^^^^^^^^^^
  File "C:\dev\coded\Lib\site-packages\django_redis\client\default.py", line 224, in set
    raise ConnectionInterrupted(connection=client) from e
django_redis.exceptions.ConnectionInterrupted: Redis ResponseError: MISCONF Redis is configured to save RDB snapshots, but it is currently not able to persist on disk. Commands that may modify the data set are disabled, because this instance is configured to report errors during writes if RDB snapshotting fails (stop-writes-on-bgsave-error option). Please check the Redis logs for details about the RDB error.

During handling of the above exception, another exception occurred:

Traceback (most recent call last):
  File "C:\dev\coded\Lib\site-packages\django\core\handlers\exception.py", line 55, in inner
    response = get_response(request)
               ^^^^^^^^^^^^^^^^^^^^^
  File "C:\Users\Coded\PRO-DEV\alx-backend-security\ip_tracking\middleware.py", line 50, in __call__
    cache.set(cache_key, ip_data, timeout=3600)  # 1h
    ^^^^^^^^^^^^^^^^^^^^^^^^^^^^^^^^^^^^^^^^^^^
  File "C:\dev\coded\Lib\site-packages\django_redis\cache.py", line 36, in _decorator
    raise e.__cause__  # noqa: B904
    ^^^^^^^^^^^^^^^^^
  File "C:\dev\coded\Lib\site-packages\django_redis\client\default.py", line 214, in set
    return bool(client.set(nkey, nvalue, nx=nx, px=timeout, xx=xx))
                ^^^^^^^^^^^^^^^^^^^^^^^^^^^^^^^^^^^^^^^^^^^^^^^^^^
  File "C:\dev\coded\Lib\site-packages\redis\commands\core.py", line 2305, in set
    return self.execute_command("SET", *pieces, **options)
           ^^^^^^^^^^^^^^^^^^^^^^^^^^^^^^^^^^^^^^^^^^^^^^^
  File "C:\dev\coded\Lib\site-packages\redis\client.py", line 621, in execute_command
    return self._execute_command(*args, **options)
           ^^^^^^^^^^^^^^^^^^^^^^^^^^^^^^^^^^^^^^^
  File "C:\dev\coded\Lib\site-packages\redis\client.py", line 632, in _execute_command
    return conn.retry.call_with_retry(
           ^^^^^^^^^^^^^^^^^^^^^^^^^^^
  File "C:\dev\coded\Lib\site-packages\redis\retry.py", line 105, in call_with_retry
    return do()
           ^^^^
  File "C:\dev\coded\Lib\site-packages\redis\client.py", line 633, in <lambda>
    lambda: self._send_command_parse_response(
            ^^^^^^^^^^^^^^^^^^^^^^^^^^^^^^^^^^
  File "C:\dev\coded\Lib\site-packages\redis\client.py", line 604, in _send_command_parse_response
    return self.parse_response(conn, command_name, **options)
           ^^^^^^^^^^^^^^^^^^^^^^^^^^^^^^^^^^^^^^^^^^^^^^^^^^
  File "C:\dev\coded\Lib\site-packages\redis\client.py", line 651, in parse_response
    response = connection.read_response()
               ^^^^^^^^^^^^^^^^^^^^^^^^^^
  File "C:\dev\coded\Lib\site-packages\redis\connection.py", line 672, in read_response
    raise response
redis.exceptions.ResponseError: MISCONF Redis is configured to save RDB snapshots, but it is currently not able to persist on disk. Commands that may modify the data set are disabled, because this instance is configured to report errors during writes if RDB snapshotting fails (stop-writes-on-bgsave-error option). Please check the Redis logs for details about the RDB error.
[2025-09-04 03:58:31,289] ERROR django.request: Internal Server Error: /login/
Traceback (most recent call last):
  File "C:\dev\coded\Lib\site-packages\django_redis\cache.py", line 29, in _decorator
    return method(self, *args, **kwargs)
           ^^^^^^^^^^^^^^^^^^^^^^^^^^^^^
  File "C:\dev\coded\Lib\site-packages\django_redis\cache.py", line 81, in set
    return self.client.set(*args, **kwargs)
           ^^^^^^^^^^^^^^^^^^^^^^^^^^^^^^^^
  File "C:\dev\coded\Lib\site-packages\django_redis\client\default.py", line 224, in set
    raise ConnectionInterrupted(connection=client) from e
django_redis.exceptions.ConnectionInterrupted: Redis ResponseError: MISCONF Redis is configured to save RDB snapshots, but it is currently not able to persist on disk. Commands that may modify the data set are disabled, because this instance is configured to report errors during writes if RDB snapshotting fails (stop-writes-on-bgsave-error option). Please check the Redis logs for details about the RDB error.

During handling of the above exception, another exception occurred:

Traceback (most recent call last):
  File "C:\dev\coded\Lib\site-packages\django\core\handlers\exception.py", line 55, in inner
    response = get_response(request)
               ^^^^^^^^^^^^^^^^^^^^^
  File "C:\Users\Coded\PRO-DEV\alx-backend-security\ip_tracking\middleware.py", line 50, in __call__
    cache.set(cache_key, ip_data, timeout=3600)  # 1h
    ^^^^^^^^^^^^^^^^^^^^^^^^^^^^^^^^^^^^^^^^^^^
  File "C:\dev\coded\Lib\site-packages\django_redis\cache.py", line 36, in _decorator
    raise e.__cause__  # noqa: B904
    ^^^^^^^^^^^^^^^^^
  File "C:\dev\coded\Lib\site-packages\django_redis\client\default.py", line 214, in set
    return bool(client.set(nkey, nvalue, nx=nx, px=timeout, xx=xx))
                ^^^^^^^^^^^^^^^^^^^^^^^^^^^^^^^^^^^^^^^^^^^^^^^^^^
  File "C:\dev\coded\Lib\site-packages\redis\commands\core.py", line 2305, in set
    return self.execute_command("SET", *pieces, **options)
           ^^^^^^^^^^^^^^^^^^^^^^^^^^^^^^^^^^^^^^^^^^^^^^^
  File "C:\dev\coded\Lib\site-packages\redis\client.py", line 621, in execute_command
    return self._execute_command(*args, **options)
           ^^^^^^^^^^^^^^^^^^^^^^^^^^^^^^^^^^^^^^^
  File "C:\dev\coded\Lib\site-packages\redis\client.py", line 632, in _execute_command
    return conn.retry.call_with_retry(
           ^^^^^^^^^^^^^^^^^^^^^^^^^^^
  File "C:\dev\coded\Lib\site-packages\redis\retry.py", line 105, in call_with_retry
    return do()
           ^^^^
  File "C:\dev\coded\Lib\site-packages\redis\client.py", line 633, in <lambda>
    lambda: self._send_command_parse_response(
            ^^^^^^^^^^^^^^^^^^^^^^^^^^^^^^^^^^
  File "C:\dev\coded\Lib\site-packages\redis\client.py", line 604, in _send_command_parse_response
    return self.parse_response(conn, command_name, **options)
           ^^^^^^^^^^^^^^^^^^^^^^^^^^^^^^^^^^^^^^^^^^^^^^^^^^
  File "C:\dev\coded\Lib\site-packages\redis\client.py", line 651, in parse_response
    response = connection.read_response()
               ^^^^^^^^^^^^^^^^^^^^^^^^^^
  File "C:\dev\coded\Lib\site-packages\redis\connection.py", line 672, in read_response
    raise response
redis.exceptions.ResponseError: MISCONF Redis is configured to save RDB snapshots, but it is currently not able to persist on disk. Commands that may modify the data set are disabled, because this instance is configured to report errors during writes if RDB snapshotting fails (stop-writes-on-bgsave-error option). Please check the Redis logs for details about the RDB error.
[2025-09-04 04:02:17,305] INFO django.utils.autoreload: Watching for file changes with StatReloader
[2025-09-04 04:02:25,554] ERROR django.request: Internal Server Error: /login/
Traceback (most recent call last):
  File "C:\dev\coded\Lib\site-packages\django_redis\cache.py", line 29, in _decorator
    return method(self, *args, **kwargs)
           ^^^^^^^^^^^^^^^^^^^^^^^^^^^^^
  File "C:\dev\coded\Lib\site-packages\django_redis\cache.py", line 81, in set
    return self.client.set(*args, **kwargs)
           ^^^^^^^^^^^^^^^^^^^^^^^^^^^^^^^^
  File "C:\dev\coded\Lib\site-packages\django_redis\client\default.py", line 224, in set
    raise ConnectionInterrupted(connection=client) from e
django_redis.exceptions.ConnectionInterrupted: Redis ResponseError: MISCONF Redis is configured to save RDB snapshots, but it is currently not able to persist on disk. Commands that may modify the data set are disabled, because this instance is configured to report errors during writes if RDB snapshotting fails (stop-writes-on-bgsave-error option). Please check the Redis logs for details about the RDB error.

During handling of the above exception, another exception occurred:

Traceback (most recent call last):
  File "C:\dev\coded\Lib\site-packages\django\core\handlers\exception.py", line 55, in inner
    response = get_response(request)
               ^^^^^^^^^^^^^^^^^^^^^
  File "C:\Users\Coded\PRO-DEV\alx-backend-security\ip_tracking\middleware.py", line 50, in __call__
    cache.set(cache_key, ip_data, timeout=3600)  # 1h
    ^^^^^^^^^^^^^^^^^^^^^^^^^^^^^^^^^^^^^^^^^^^
  File "C:\dev\coded\Lib\site-packages\django_redis\cache.py", line 36, in _decorator
    raise e.__cause__  # noqa: B904
    ^^^^^^^^^^^^^^^^^
  File "C:\dev\coded\Lib\site-packages\django_redis\client\default.py", line 214, in set
    return bool(client.set(nkey, nvalue, nx=nx, px=timeout, xx=xx))
                ^^^^^^^^^^^^^^^^^^^^^^^^^^^^^^^^^^^^^^^^^^^^^^^^^^
  File "C:\dev\coded\Lib\site-packages\redis\commands\core.py", line 2305, in set
    return self.execute_command("SET", *pieces, **options)
           ^^^^^^^^^^^^^^^^^^^^^^^^^^^^^^^^^^^^^^^^^^^^^^^
  File "C:\dev\coded\Lib\site-packages\redis\client.py", line 621, in execute_command
    return self._execute_command(*args, **options)
           ^^^^^^^^^^^^^^^^^^^^^^^^^^^^^^^^^^^^^^^
  File "C:\dev\coded\Lib\site-packages\redis\client.py", line 632, in _execute_command
    return conn.retry.call_with_retry(
           ^^^^^^^^^^^^^^^^^^^^^^^^^^^
  File "C:\dev\coded\Lib\site-packages\redis\retry.py", line 105, in call_with_retry
    return do()
           ^^^^
  File "C:\dev\coded\Lib\site-packages\redis\client.py", line 633, in <lambda>
    lambda: self._send_command_parse_response(
            ^^^^^^^^^^^^^^^^^^^^^^^^^^^^^^^^^^
  File "C:\dev\coded\Lib\site-packages\redis\client.py", line 604, in _send_command_parse_response
    return self.parse_response(conn, command_name, **options)
           ^^^^^^^^^^^^^^^^^^^^^^^^^^^^^^^^^^^^^^^^^^^^^^^^^^
  File "C:\dev\coded\Lib\site-packages\redis\client.py", line 651, in parse_response
    response = connection.read_response()
               ^^^^^^^^^^^^^^^^^^^^^^^^^^
  File "C:\dev\coded\Lib\site-packages\redis\connection.py", line 672, in read_response
    raise response
redis.exceptions.ResponseError: MISCONF Redis is configured to save RDB snapshots, but it is currently not able to persist on disk. Commands that may modify the data set are disabled, because this instance is configured to report errors during writes if RDB snapshotting fails (stop-writes-on-bgsave-error option). Please check the Redis logs for details about the RDB error.
[2025-09-04 04:03:53,189] INFO django.utils.autoreload: Watching for file changes with StatReloader
[2025-09-04 04:04:00,283] ERROR django.request: Internal Server Error: /login/
Traceback (most recent call last):
  File "C:\dev\coded\Lib\site-packages\django_redis\cache.py", line 29, in _decorator
    return method(self, *args, **kwargs)
           ^^^^^^^^^^^^^^^^^^^^^^^^^^^^^
  File "C:\dev\coded\Lib\site-packages\django_redis\cache.py", line 81, in set
    return self.client.set(*args, **kwargs)
           ^^^^^^^^^^^^^^^^^^^^^^^^^^^^^^^^
  File "C:\dev\coded\Lib\site-packages\django_redis\client\default.py", line 224, in set
    raise ConnectionInterrupted(connection=client) from e
django_redis.exceptions.ConnectionInterrupted: Redis ResponseError: MISCONF Redis is configured to save RDB snapshots, but it is currently not able to persist on disk. Commands that may modify the data set are disabled, because this instance is configured to report errors during writes if RDB snapshotting fails (stop-writes-on-bgsave-error option). Please check the Redis logs for details about the RDB error.

During handling of the above exception, another exception occurred:

Traceback (most recent call last):
  File "C:\dev\coded\Lib\site-packages\django\core\handlers\exception.py", line 55, in inner
    response = get_response(request)
               ^^^^^^^^^^^^^^^^^^^^^
  File "C:\Users\Coded\PRO-DEV\alx-backend-security\ip_tracking\middleware.py", line 50, in __call__
    cache.set(cache_key, ip_data, timeout=3600)  # 1h
    ^^^^^^^^^^^^^^^^^^^^^^^^^^^^^^^^^^^^^^^^^^^
  File "C:\dev\coded\Lib\site-packages\django_redis\cache.py", line 36, in _decorator
    raise e.__cause__  # noqa: B904
    ^^^^^^^^^^^^^^^^^
  File "C:\dev\coded\Lib\site-packages\django_redis\client\default.py", line 214, in set
    return bool(client.set(nkey, nvalue, nx=nx, px=timeout, xx=xx))
                ^^^^^^^^^^^^^^^^^^^^^^^^^^^^^^^^^^^^^^^^^^^^^^^^^^
  File "C:\dev\coded\Lib\site-packages\redis\commands\core.py", line 2305, in set
    return self.execute_command("SET", *pieces, **options)
           ^^^^^^^^^^^^^^^^^^^^^^^^^^^^^^^^^^^^^^^^^^^^^^^
  File "C:\dev\coded\Lib\site-packages\redis\client.py", line 621, in execute_command
    return self._execute_command(*args, **options)
           ^^^^^^^^^^^^^^^^^^^^^^^^^^^^^^^^^^^^^^^
  File "C:\dev\coded\Lib\site-packages\redis\client.py", line 632, in _execute_command
    return conn.retry.call_with_retry(
           ^^^^^^^^^^^^^^^^^^^^^^^^^^^
  File "C:\dev\coded\Lib\site-packages\redis\retry.py", line 105, in call_with_retry
    return do()
           ^^^^
  File "C:\dev\coded\Lib\site-packages\redis\client.py", line 633, in <lambda>
    lambda: self._send_command_parse_response(
            ^^^^^^^^^^^^^^^^^^^^^^^^^^^^^^^^^^
  File "C:\dev\coded\Lib\site-packages\redis\client.py", line 604, in _send_command_parse_response
    return self.parse_response(conn, command_name, **options)
           ^^^^^^^^^^^^^^^^^^^^^^^^^^^^^^^^^^^^^^^^^^^^^^^^^^
  File "C:\dev\coded\Lib\site-packages\redis\client.py", line 651, in parse_response
    response = connection.read_response()
               ^^^^^^^^^^^^^^^^^^^^^^^^^^
  File "C:\dev\coded\Lib\site-packages\redis\connection.py", line 672, in read_response
    raise response
redis.exceptions.ResponseError: MISCONF Redis is configured to save RDB snapshots, but it is currently not able to persist on disk. Commands that may modify the data set are disabled, because this instance is configured to report errors during writes if RDB snapshotting fails (stop-writes-on-bgsave-error option). Please check the Redis logs for details about the RDB error.
[2025-09-04 04:18:46,520] INFO django.utils.autoreload: Watching for file changes with StatReloader
[2025-09-04 04:19:00,743] ERROR django.request: Internal Server Error: /login/
Traceback (most recent call last):
  File "C:\dev\coded\Lib\site-packages\django_redis\cache.py", line 29, in _decorator
    return method(self, *args, **kwargs)
           ^^^^^^^^^^^^^^^^^^^^^^^^^^^^^
  File "C:\dev\coded\Lib\site-packages\django_redis\cache.py", line 81, in set
    return self.client.set(*args, **kwargs)
           ^^^^^^^^^^^^^^^^^^^^^^^^^^^^^^^^
  File "C:\dev\coded\Lib\site-packages\django_redis\client\default.py", line 224, in set
    raise ConnectionInterrupted(connection=client) from e
django_redis.exceptions.ConnectionInterrupted: Redis ResponseError: MISCONF Redis is configured to save RDB snapshots, but it is currently not able to persist on disk. Commands that may modify the data set are disabled, because this instance is configured to report errors during writes if RDB snapshotting fails (stop-writes-on-bgsave-error option). Please check the Redis logs for details about the RDB error.

During handling of the above exception, another exception occurred:

Traceback (most recent call last):
  File "C:\dev\coded\Lib\site-packages\django\core\handlers\exception.py", line 55, in inner
    response = get_response(request)
               ^^^^^^^^^^^^^^^^^^^^^
  File "C:\Users\Coded\PRO-DEV\alx-backend-security\ip_tracking\middleware.py", line 50, in __call__
    cache.set(cache_key, ip_data, timeout=3600)  # 1h
    ^^^^^^^^^^^^^^^^^^^^^^^^^^^^^^^^^^^^^^^^^^^
  File "C:\dev\coded\Lib\site-packages\django_redis\cache.py", line 36, in _decorator
    raise e.__cause__  # noqa: B904
    ^^^^^^^^^^^^^^^^^
  File "C:\dev\coded\Lib\site-packages\django_redis\client\default.py", line 214, in set
    return bool(client.set(nkey, nvalue, nx=nx, px=timeout, xx=xx))
                ^^^^^^^^^^^^^^^^^^^^^^^^^^^^^^^^^^^^^^^^^^^^^^^^^^
  File "C:\dev\coded\Lib\site-packages\redis\commands\core.py", line 2305, in set
    return self.execute_command("SET", *pieces, **options)
           ^^^^^^^^^^^^^^^^^^^^^^^^^^^^^^^^^^^^^^^^^^^^^^^
  File "C:\dev\coded\Lib\site-packages\redis\client.py", line 621, in execute_command
    return self._execute_command(*args, **options)
           ^^^^^^^^^^^^^^^^^^^^^^^^^^^^^^^^^^^^^^^
  File "C:\dev\coded\Lib\site-packages\redis\client.py", line 632, in _execute_command
    return conn.retry.call_with_retry(
           ^^^^^^^^^^^^^^^^^^^^^^^^^^^
  File "C:\dev\coded\Lib\site-packages\redis\retry.py", line 105, in call_with_retry
    return do()
           ^^^^
  File "C:\dev\coded\Lib\site-packages\redis\client.py", line 633, in <lambda>
    lambda: self._send_command_parse_response(
            ^^^^^^^^^^^^^^^^^^^^^^^^^^^^^^^^^^
  File "C:\dev\coded\Lib\site-packages\redis\client.py", line 604, in _send_command_parse_response
    return self.parse_response(conn, command_name, **options)
           ^^^^^^^^^^^^^^^^^^^^^^^^^^^^^^^^^^^^^^^^^^^^^^^^^^
  File "C:\dev\coded\Lib\site-packages\redis\client.py", line 651, in parse_response
    response = connection.read_response()
               ^^^^^^^^^^^^^^^^^^^^^^^^^^
  File "C:\dev\coded\Lib\site-packages\redis\connection.py", line 672, in read_response
    raise response
redis.exceptions.ResponseError: MISCONF Redis is configured to save RDB snapshots, but it is currently not able to persist on disk. Commands that may modify the data set are disabled, because this instance is configured to report errors during writes if RDB snapshotting fails (stop-writes-on-bgsave-error option). Please check the Redis logs for details about the RDB error.
[2025-09-04 04:40:36,678] INFO django.utils.autoreload: Watching for file changes with StatReloader
[2025-09-04 04:40:46,086] INFO ip_tracking.middleware: [127.0.0.1] (None, None) -> /login/ | Count: 1
[2025-09-04 04:40:48,744] INFO ip_tracking.middleware: [127.0.0.1] (None, None) -> /login/ | Count: 2
[2025-09-04 04:40:49,779] INFO ip_tracking.middleware: [127.0.0.1] (None, None) -> /login/ | Count: 3
[2025-09-04 04:40:50,612] INFO ip_tracking.middleware: [127.0.0.1] (None, None) -> /login/ | Count: 4
[2025-09-04 04:40:51,303] INFO ip_tracking.middleware: [127.0.0.1] (None, None) -> /login/ | Count: 5
[2025-09-04 04:40:52,055] INFO ip_tracking.middleware: [127.0.0.1] (None, None) -> /login/ | Count: 6
[2025-09-04 04:40:52,909] INFO ip_tracking.middleware: [127.0.0.1] (None, None) -> /login/ | Count: 7
[2025-09-04 04:40:53,630] INFO ip_tracking.middleware: [127.0.0.1] (None, None) -> /login/ | Count: 8
[2025-09-04 04:40:54,296] INFO ip_tracking.middleware: [127.0.0.1] (None, None) -> /login/ | Count: 9
[2025-09-04 04:40:54,902] INFO ip_tracking.middleware: [127.0.0.1] (None, None) -> /login/ | Count: 10
[2025-09-04 04:40:55,075] INFO ip_tracking.middleware: [127.0.0.1] (None, None) -> /login/ | Count: 11
[2025-09-04 04:40:55,247] INFO ip_tracking.middleware: [127.0.0.1] (None, None) -> /login/ | Count: 12
[2025-09-04 04:40:55,415] INFO ip_tracking.middleware: [127.0.0.1] (None, None) -> /login/ | Count: 13
[2025-09-04 04:40:55,576] INFO ip_tracking.middleware: [127.0.0.1] (None, None) -> /login/ | Count: 14
[2025-09-04 04:40:55,728] INFO ip_tracking.middleware: [127.0.0.1] (None, None) -> /login/ | Count: 15
[2025-09-04 04:40:55,894] INFO ip_tracking.middleware: [127.0.0.1] (None, None) -> /login/ | Count: 16
[2025-09-04 04:40:56,068] INFO ip_tracking.middleware: [127.0.0.1] (None, None) -> /login/ | Count: 17
[2025-09-04 04:40:56,210] INFO ip_tracking.middleware: [127.0.0.1] (None, None) -> /login/ | Count: 18
[2025-09-04 04:40:56,380] INFO ip_tracking.middleware: [127.0.0.1] (None, None) -> /login/ | Count: 19
[2025-09-04 04:40:56,536] INFO ip_tracking.middleware: [127.0.0.1] (None, None) -> /login/ | Count: 20
[2025-09-04 04:40:56,749] INFO ip_tracking.middleware: [127.0.0.1] (None, None) -> /login/ | Count: 21
[2025-09-04 04:46:42,163] INFO django.utils.autoreload: C:\Users\Coded\PRO-DEV\alx-backend-security\ip_tracking\views.py changed, reloading.
[2025-09-04 04:46:43,428] INFO django.utils.autoreload: Watching for file changes with StatReloader
[2025-09-04 04:47:03,298] INFO ip_tracking.middleware: [127.0.0.1] (None, None) -> /login/ | Count: 22
[2025-09-04 04:47:05,332] INFO ip_tracking.middleware: [127.0.0.1] (None, None) -> /login/ | Count: 23
[2025-09-04 04:47:07,146] INFO ip_tracking.middleware: [127.0.0.1] (None, None) -> /login/ | Count: 24
[2025-09-04 04:47:08,059] INFO ip_tracking.middleware: [127.0.0.1] (None, None) -> /login/ | Count: 25
[2025-09-04 04:47:08,777] INFO ip_tracking.middleware: [127.0.0.1] (None, None) -> /login/ | Count: 26
[2025-09-04 04:47:09,458] INFO ip_tracking.middleware: [127.0.0.1] (None, None) -> /login/ | Count: 27
[2025-09-04 04:47:10,108] INFO ip_tracking.middleware: [127.0.0.1] (None, None) -> /login/ | Count: 28
[2025-09-04 04:47:10,629] INFO ip_tracking.middleware: [127.0.0.1] (None, None) -> /login/ | Count: 29
[2025-09-04 04:47:11,218] INFO ip_tracking.middleware: [127.0.0.1] (None, None) -> /login/ | Count: 30
[2025-09-04 04:47:12,020] INFO ip_tracking.middleware: [127.0.0.1] (None, None) -> /login/ | Count: 31
[2025-09-04 04:47:12,813] INFO ip_tracking.middleware: [127.0.0.1] (None, None) -> /login/ | Count: 32
[2025-09-04 04:47:13,516] INFO ip_tracking.middleware: [127.0.0.1] (None, None) -> /login/ | Count: 33
[2025-09-04 04:47:14,104] INFO ip_tracking.middleware: [127.0.0.1] (None, None) -> /login/ | Count: 34
[2025-09-04 04:47:14,780] INFO ip_tracking.middleware: [127.0.0.1] (None, None) -> /login/ | Count: 35
[2025-09-04 04:47:15,236] INFO ip_tracking.middleware: [127.0.0.1] (None, None) -> /login/ | Count: 36
[2025-09-04 04:47:15,570] INFO ip_tracking.middleware: [127.0.0.1] (None, None) -> /login/ | Count: 37
[2025-09-04 04:47:15,953] INFO ip_tracking.middleware: [127.0.0.1] (None, None) -> /login/ | Count: 38
[2025-09-04 04:47:16,136] INFO ip_tracking.middleware: [127.0.0.1] (None, None) -> /login/ | Count: 39
[2025-09-04 04:47:16,318] INFO ip_tracking.middleware: [127.0.0.1] (None, None) -> /login/ | Count: 40
[2025-09-04 04:47:16,501] INFO ip_tracking.middleware: [127.0.0.1] (None, None) -> /login/ | Count: 41
[2025-09-04 04:47:16,679] INFO ip_tracking.middleware: [127.0.0.1] (None, None) -> /login/ | Count: 42
[2025-09-04 04:47:16,856] INFO ip_tracking.middleware: [127.0.0.1] (None, None) -> /login/ | Count: 43
[2025-09-04 04:47:17,024] INFO ip_tracking.middleware: [127.0.0.1] (None, None) -> /login/ | Count: 44
[2025-09-04 04:47:17,190] INFO ip_tracking.middleware: [127.0.0.1] (None, None) -> /login/ | Count: 45
[2025-09-04 04:47:17,360] INFO ip_tracking.middleware: [127.0.0.1] (None, None) -> /login/ | Count: 46
[2025-09-04 04:47:17,587] INFO ip_tracking.middleware: [127.0.0.1] (None, None) -> /login/ | Count: 47
[2025-09-04 04:48:46,197] INFO django.utils.autoreload: C:\Users\Coded\PRO-DEV\alx-backend-security\ip_tracking\views.py changed, reloading.
[2025-09-04 04:48:47,357] INFO django.utils.autoreload: Watching for file changes with StatReloader
[2025-09-04 04:54:31,126] INFO django.utils.autoreload: C:\Users\Coded\PRO-DEV\alx-backend-security\alx_backend_security\settings.py changed, reloading.
[2025-09-04 04:54:32,553] INFO django.utils.autoreload: Watching for file changes with StatReloader
[2025-09-04 04:54:39,767] INFO django.utils.autoreload: C:\Users\Coded\PRO-DEV\alx-backend-security\alx_backend_security\settings.py changed, reloading.
[2025-09-04 04:54:40,972] INFO django.utils.autoreload: Watching for file changes with StatReloader
